Workbook

Sheet Levantamento Campo
B1: Prj Estande de Tiro (50 m) – 5º BIL (Amv)
B3: LEVANTAMENTO DE CAMPO
E5: Dimensões | J5: Vãos | O5: Alvenarias Adicionais
B6: Ambiente | E6: C | F6: L | G6: h | H6: e | I6: A | J6: Tipo | K6: C | L6: h | M6: e | N6: A | O6: Tipo | P6: C | Q6: h | R6: e | S6: V
E7: [m] | F7: [m] | G7: [m] | H7: [m] | I7: [m²] | K7: [m] | L7: [m] | M7: [m] | N7: [m²] | P7: [m] | Q7: [m] | R7: [m] | S7: [m³]
I8: =E8*F8 -> 0 | N8: =K8*L8 -> 0 | S8: =R8*Q8*P8 -> 0
I9: =E9*F9 -> 0 | N9: =K9*L9 -> 0 | S9: =R9*Q9*P9 -> 0
I10: =E10*F10 -> 0 | N10: =K10*L10 -> 0 | S10: =R10*Q10*P10 -> 0
I11: =E11*F11 -> 0 | N11: =K11*L11 -> 0 | S11: =R11*Q11*P11 -> 0
I12: =E12*F12 -> 0 | N12: =K12*L12 -> 0 | S12: =R12*Q12*P12 -> 0
I13: =E13*F13 -> 0 | N13: =K13*L13 -> 0 | S13: =R13*Q13*P13 -> 0
I14: =E14*F14 -> 0 | N14: =K14*L14 -> 0 | S14: =R14*Q14*P14 -> 0
I15: =E15*F15 -> 0 | N15: =K15*L15 -> 0 | S15: =R15*Q15*P15 -> 0
I16: =E16*F16 -> 0 | N16: =K16*L16 -> 0 | S16: =R16*Q16*P16 -> 0
I17: =E17*F17 -> 0 | N17: =K17*L17 -> 0 | S17: =R17*Q17*P17 -> 0
I18: =E18*F18 -> 0 | N18: =K18*L18 -> 0 | S18: =R18*Q18*P18 -> 0
I19: =E19*F19 -> 0 | N19: =K19*L19 -> 0 | S19: =R19*Q19*P19 -> 0
... I108: =E108*F108 -> 0 | N108: =K108*L108 -> 0 | S108: =R108*Q108*P108 -> 0
E111: Pilar | I111: Viga | M111: Laje
B112: Ambiente | E112: C | F112: L | G112: h | H112: A | I112: C | J112: h | K112: e | L112: A | M112: C | N112: L | O112: e | P112: A
E113: [m] | F113: [m] | G113: [m] | H113: [m²] | I113: [m] | J113: [m] | K113: [m] | L113: [m²] | M113: [m] | N113: [m] | O113: [m] | P113: [m²]
B114: =B8 -> 0 | H114: =E114*F114 -> 0 | L114: =I114*J114 -> 0 | P114: =O114*N114*M114 -> 0
B115: =B9 -> 0 | H115: =E115*F115 -> 0 | L115: =I115*J115 -> 0 | P115: =O115*N115*M115 -> 0
B116: =B10 -> 0 | H116: =E116*F116 -> 0 | L116: =I116*J116 -> 0 | P116: =O116*N116*M116 -> 0
B117: =B11 -> 0 | H117: =E117*F117 -> 0 | L117: =I117*J117 -> 0 | P117: =O117*N117*M117 -> 0
B118: =B12 -> 0 | H118: =E118*F118 -> 0 | L118: =I118*J118 -> 0 | P118: =O118*N118*M118 -> 0
B119: =B13 -> 0 | H119: =E119*F119 -> 0 | L119: =I119*J119 -> 0 | P119: =O119*N119*M119 -> 0
B120: =B14 -> 0 | H120: =E120*F120 -> 0 | L120: =I120*J120 -> 0 | P120: =O120*N120*M120 -> 0
B121: =B15 -> 0 | H121: =E121*F121 -> 0 | L121: =I121*J121 -> 0 | P121: =O121*N121*M121 -> 0
B122: =B16 -> 0 | H122: =E122*F122 -> 0 | L122: =I122*J122 -> 0 | P122: =O122*N122*M122 -> 0
B123: =B17 -> 0 | H123: =E123*F123 -> 0 | L123: =I123*J123 -> 0 | P123: =O123*N123*M123 -> 0
B124: =B18 -> 0 | H124: =E124*F124 -> 0 | L124: =I124*J124 -> 0 | P124: =O124*N124*M124 -> 0
B125: =B19 -> 0 | H125: =E125*F125 -> 0 | L125: =I125*J125 -> 0 | P125: =O125*N125*M125 -> 0
... B129: =B23 -> 0 | H129: =E129*F129 -> 0 | L129: =I129*J129 -> 0 | P129: =O129*N129*M129 -> 0
B130: =B83 -> 0 | H130: =E130*F130 -> 0 | L130: =I130*J130 -> 0 | P130: =O130*N130*M130 -> 0
B131: =B84 -> 0 | H131: =E131*F131 -> 0 | L131: =I131*J131 -> 0 | P131: =O131*N131*M131 -> 0
B132: =B85 -> 0 | H132: =E132*F132 -> 0 | L132: =I132*J132 -> 0 | P132: =O132*N132*M132 -> 0
B133: =B27 -> 0 | H133: =E133*F133 -> 0 | L133: =I133*J133 -> 0 | P133: =O133*N133*M133 -> 0
B134: =B71 -> 0 | H134: =E134*F134 -> 0 | L134: =I134*J134 -> 0 | P134: =O134*N134*M134 -> 0
B135: =B72 -> 0 | H135: =E135*F135 -> 0 | L135: =I135*J135 -> 0 | P135: =O135*N135*M135 -> 0
...

Sheet Serviços Preliminares
B1: ='Levantamento Campo'!B1 -> Prj Estande de Tiro (50 m) – 5º BIL (Amv)
A3: 1. | B3: SERVIÇOS PRELIMINARES
A5: 1.1 | B5: Limpeza Inicial
B7: Limpeza
B8: A [m²]
B9: =SUM('Levantamento Campo'!G9:G109) -> 0
A11: 1.2 | B11: Implantação de Canteiro de Obra
A17: 1.3 | B17: Alocação de Contêineres
A23: 1.4 | B23: Alocação de Banheiros Químicos
A29: 1.5 | B29: Alocação de Andaimes
A35: 1.6 | B35: Interdições no Local da Obra e Adjacências
B37: Fase | C37: Ambiente | E37: Local | G37: A [m²]
F42: Total | G42: =SUM(G38:G41) -> 0
A44: 1.7 | B44: Remoções | AG44: Recolocações
E46: Elétrica/SPDA/Rede | O46: Água Fria/Água Pluvial/Esgoto/Pressurizadas/Contra Incêndio | X46: Esquadrias | Z46: Telhados | AC46: Equipamentos/Acessórios | AG46: Equipamentos/Acessórios
B47: Ambiente | E47: Condulete | F47: Tomadas | G47: Interruptor | H47: Luminária | I47: Dutos | J47: Cabos | K47: Captação | L47: Aterra/o | M47: Quadros | N47: Postes | O47: Cavalete | P47: Reservat | Q47: Registros | R47: Válvulas | S47: Torneiras | T47: Dutos | U47: Calhas | V47: Caixas | W47: Drenos | X47: Portas | Y47: Janelas | Z47: Telha | AA47: Trama | AB47: Tesoura | AC47: Item | AE47: Qtd | AG47: Item | AI47: Qtd
E48: [m] | F48: [Un] | G48: [Un] | H48: [Un] | I48: [m] | J48: [m] | K48: [m] | L48: [m] | M48: [Un] | N48: [Un] | O48: [Un] | P48: [Un] | Q48: [Un] | R48: [Un] | S48: [Un] | T48: [m] | U48: [m] | V48: [Un] | W48: [Un] | X48: [m²] | Y48: [m²] | Z48: [m²] | AA48: [m²] | AB48: [Un] | AE48: [Un] | AI48: [Un]
B49: ='Levantamento Campo'!B8 -> 0
B50: ='Levantamento Campo'!B9 -> 0
B51: ='Levantamento Campo'!B10 -> 0
B52: ='Levantamento Campo'!B11 -> 0
B53: ='Levantamento Campo'!B12 -> 0
B54: ='Levantamento Campo'!B13 -> 0
B55: ='Levantamento Campo'!B14 -> 0
B56: ='Levantamento Campo'!B15 -> 0
B57: ='Levantamento Campo'!B16 -> 0
B58: ='Levantamento Campo'!B17 -> 0
B59: ='Levantamento Campo'!B18 -> 0
B60: ='Levantamento Campo'!B19 -> 0
... B64: ='Levantamento Campo'!B23 -> 0
B65: ='Levantamento Campo'!B83 -> 0
B66: ='Levantamento Campo'!B84 -> 0
B67: ='Levantamento Campo'!B85 -> 0
B68: ='Levantamento Campo'!B108 -> 0
B69: Total | E69: =SUM(E49:E68) -> 0 | F69: =SUM(F49:F68) -> 0 | G69: =SUM(G49:G68) -> 0 | H69: =SUM(H49:H68) -> 0 | I69: =SUM(I49:I68) -> 0 | J69: =SUM(J49:J68) -> 0 | K69: =SUM(K49:K68) -> 0 | L69: =SUM(L49:L68) -> 0 | ... AB69: =SUM(AB49:AB68) -> 0 | AE69: =SUM(AE49:AE68) -> 0
A71: 1.8 | B71: Demolições
E73: Piso | F73: Rodapé | G73: Azulejo | H73: Forro | I73: Alvenaria | K73: Estrutura
B74: Ambiente | I74: Tipo | J74: V | K74: Fundação | L74: Pilar | M74: Viga | N74: Laje | AI74: =SUM(AI49:AI73) -> 0
E75: [m²] | F75: [m] | G75: [m²] | H75: [m²] | J75: [m³] | K75: [m³] | L75: [m³] | M75: [m³] | N75: [m³]
B76: ='Levantamento Campo'!B8 -> 0
...

Sheet Movimento de Solo
B1: ='Levantamento Campo'!B1 -> Prj Estande de Tiro (50 m) – 5º BIL (Amv)
A3: 2. | B3: MOVIMENTO de SOLOS
A5: 2.1 | B5: Terraplanagem
A13: 2.2 | B13: Escavações
B15: Ambiente | E15: Tipo | F15: i | G15: L | H15: C | I15: h | J15: Lastro | K15: A | L15: V
F16: [%] | G16: [m] | H16: [m] | I16: [m] | J16: [m³] | K16: [m²] | L16: [m³]
B17: ='Levantamento Campo'!B8 -> 0
B18: ='Levantamento Campo'!B9 -> 0
B19: ='Levantamento Campo'!B10 -> 0
B20: ='Levantamento Campo'!B11 -> 0
B21: ='Levantamento Campo'!B12 -> 0
B22: ='Levantamento Campo'!B13 -> 0
B23: ='Levantamento Campo'!B14 -> 0
B24: ='Levantamento Campo'!B15 -> 0
B25: ='Levantamento Campo'!B16 -> 0
B26: ='Levantamento Campo'!B17 -> 0
B27: ='Levantamento Campo'!B18 -> 0
B28: ='Levantamento Campo'!B19 -> 0
... B32: ='Levantamento Campo'!B23 -> 0
B33: ='Levantamento Campo'!B83 -> 0
B34: ='Levantamento Campo'!B84 -> 0
B35: ='Levantamento Campo'!B85 -> 0
B36: ='Levantamento Campo'!B108 -> 0
B37: Total | J37: =SUM(J17:J36) -> 0 | K37: =SUM(K17:K36) -> 0 | L37: =SUM(L17:L36) -> 0
A39: 2.3 | B39: Aterros e Reaterros
B41: Ambiente | E41: i | F41: L | G41: C | H41: h | I41: A | J41: V
E42: [%] | F42: [m] | G42: [m] | H42: [m] | I42: [m²] | J42: [m³]
B43: ='Levantamento Campo'!B8 -> 0
B44: ='Levantamento Campo'!B9 -> 0
B45: ='Levantamento Campo'!B10 -> 0
B46: ='Levantamento Campo'!B11 -> 0
B47: ='Levantamento Campo'!B12 -> 0
B48: ='Levantamento Campo'!B13 -> 0
B49: ='Levantamento Campo'!B14 -> 0
B50: ='Levantamento Campo'!B15 -> 0
B51: ='Levantamento Campo'!B16 -> 0
B52: ='Levantamento Campo'!B17 -> 0
B53: ='Levantamento Campo'!B18 -> 0
B54: ='Levantamento Campo'!B19 -> 0
... B58: ='Levantamento Campo'!B23 -> 0
...

Sheet Estruturas
B1: ='Levantamento Campo'!B1 -> Prj Estande de Tiro (50 m) – 5º BIL (Amv)
A3: 3. | B3: ESTRUTURAS
A5: 3.1 | B5: Fundações
A7: 3.1.1 | B7: Sistema Viga Baldrame
E9: Peça | F9: Seção | H9: C | I9: Lastro | J9: Concreto | K9: Ferragem | L9: Estribo | M9: Forma em Madeira
B10: Ambiente | F10: L | G10: h | M10: L | N10: C | O10: A
F11: [m] | G11: [m] | H11: [m] | I11: [m³] | J11: [m³] | K11: [KgF] | L11: [KgF] | M11: [m] | N11: [m] | O11: [m²]
O12: =M12*N12 -> 0
O13: =M13*N13 -> 0
O14: =M14*N14 -> 0
O15: =M15*N15 -> 0
O16: =M16*N16 -> 0
O17: =M17*N17 -> 0
O18: =M18*N18 -> 0
O19: =M19*N19 -> 0
O20: =M20*N20 -> 0
O21: =M21*N21 -> 0
O22: =M22*N22 -> 0
O23: =M23*N23 -> 0
... O31: =M31*N31 -> 0
B32: Total | I32: =SUM(I20:I31) -> 0 | J32: =SUM(J20:J31) -> 0 | K32: =SUM(K20:K31) -> 0 | L32: =SUM(L20:L31) -> 0 | N32: =SUM(N20:N31) -> 0 | O32: =SUM(O20:O31) -> 0
A34: 3.1.2 | B34: Estacas e Blocos de Coroamento
E36: Peça | F36: Valores por Peça | I36: Valores Totais | M36: Forma em Madeira
B37: Ambiente | F37: L | G37: h | H37: C | I37: Lastro | J37: Concreto | K37: Ferragem | L37: Estribo | M37: L | N37: C | O37: A Tot
F38: [m] | G38: [m] | H38: [m] | I38: [m³] | J38: [m³] | K38: [KgF] | L38: [KgF] | M38: [m] | N38: [m] | O38: [m²]
O39: =M39*N39 -> 0
O40: =M40*N40 -> 0
O41: =M41*N41 -> 0
O42: =M42*N42 -> 0
O43: =M43*N43 -> 0
O44: =M44*N44 -> 0
O45: =M45*N45 -> 0
O46: =M46*N46 -> 0
O47: =M47*N47 -> 0
O48: =M48*N48 -> 0
O49: =M49*N49 -> 0
O50: =M50*N50 -> 0
... O58: =M58*N58 -> 0
B59: Total | I59: =SUM(I39:I58) -> 0 | J59: =SUM(J39:J58) -> 0 | K59: =SUM(K39:K58) -> 0 | L59: =SUM(L39:L58) -> 0 | N59: =SUM(N39:N58) -> 0 | O59: =SUM(O39:O58) -> 0
A61: 3.1.3 | B61: Estacas
...

Sheet Alvenarias
B1: ='Levantamento Campo'!B1 -> Prj Estande de Tiro (50 m) – 5º BIL (Amv)
A3: 4. | B3: ALVENARIAS
A5: 4.1 | B5: Painéis
E7: Painéis em Alvenaria | K7: Painéis em Gesso Acartonado | Q7: Painéis Cobogó ou em Blocos de Vidro
B8: Ambiente | E8: Peça | F8: C | G8: L | H8: h | I8: Vãos | J8: A | K8: Peça | L8: C | M8: L | N8: h | O8: Vãos | P8: A | Q8: Peça | R8: C | S8: L | T8: h | U8: Vãos | V8: A
F9: [m] | G9: [m] | H9: [m] | I9: [m²] | J9: [m²] | L9: [m] | M9: [m] | N9: [m] | O9: [m²] | P9: [m²] | R9: [m] | S9: [m] | T9: [m] | U9: [m²] | V9: [m²]
B10: ='Levantamento Campo'!B8 -> 0
B11: ='Levantamento Campo'!B9 -> 0
B12: ='Levantamento Campo'!B10 -> 0
B13: ='Levantamento Campo'!B11 -> 0
B14: ='Levantamento Campo'!B12 -> 0
B15: ='Levantamento Campo'!B13 -> 0
B16: ='Levantamento Campo'!B14 -> 0
B17: ='Levantamento Campo'!B15 -> 0
B18: ='Levantamento Campo'!B16 -> 0
B19: ='Levantamento Campo'!B17 -> 0
B20: ='Levantamento Campo'!B18 -> 0
B21: ='Levantamento Campo'!B19 -> 0
... B25: ='Levantamento Campo'!B23 -> 0
B26: ='Levantamento Campo'!B83 -> 0
B27: ='Levantamento Campo'!B84 -> 0
B28: ='Levantamento Campo'!B85 -> 0
B29: ='Levantamento Campo'!B108 -> 0
B30: Total | J30: =SUM(J10:J29) -> 0 | P30: =SUM(P10:P29) -> 0
A32: 4.2 | B32: Vergas e Contra Vergas
B34: Ambiente | E34: Peça | F34: Qtd | H34: L | I34: C | J34: h | K34: Engasta/o | L34: Concreto | M34: Ferragem
F35: Verga | G35: C Verga | H35: [m] | I35: [m] | J35: [m] | K35: [m] | L35: [m³] | M35: [KgF]
B36: ='Levantamento Campo'!B8 -> 0
B37: ='Levantamento Campo'!B9 -> 0
B38: ='Levantamento Campo'!B10 -> 0
B39: ='Levantamento Campo'!B11 -> 0
B40: ='Levantamento Campo'!B12 -> 0
B41: ='Levantamento Campo'!B13 -> 0
B42: ='Levantamento Campo'!B14 -> 0
B43: ='Levantamento Campo'!B15 -> 0
B44: ='Levantamento Campo'!B16 -> 0
B45: ='Levantamento Campo'!B17 -> 0
B46: ='Levantamento Campo'!B18 -> 0
B47: ='Levantamento Campo'!B19 -> 0
... B51: ='Levantamento Campo'!B23 -> 0
...

Sheet Acabamentos
B1: ='Levantamento Campo'!B1 -> Prj Estande de Tiro (50 m) – 5º BIL (Amv)
E4: Pisos | L4: Soleiras | P4: Rodapés
E5: Tipo | F5: Dimensões | J5: Placa Cerâmica | L5: Tipo | M5: Dimensões | P5: Tipo | Q5: Dimensões
B6: Ambiente | F6: e | G6: C | H6: L | I6: A | J6: C | K6: L | M6: e | N6: C | O6: L | Q6: h | R6: C | S6: L | T6: A
F7: [m] | G7: [m] | H7: [m] | I7: [m²] | J7: [m] | K7: [m] | M7: [m] | N7: [m] | O7: [m] | Q7: [m] | R7: [m] | S7: [m] | T7: [m²]
B28: Total | I28: =SUM(I8:I27) -> 0 | N28: =SUM(N8:N27) -> 0 | R28: =SUM(R8:R27) -> 0
E31: Azulejos e Rodabancas | L31: Peitoris | P31: Forros
B32: Ambiente | E32: Tipo | F32: Dimensões | J32: Placa | L32: Tipo | M32: Dimensões | P32: Tipo | Q32: Dimensões | T32: Placa
F33: e | G33: h | H33: CTot | I33: A | J33: L | K33: C | M33: e | N33: L | O33: C | Q33: L | R33: C | S33: A | T33: L | U33: C
F34: [m] | G34: [m] | H34: [m] | I34: [m²] | J34: [m] | K34: [m] | M34: [m] | N34: [m] | O34: [m] | Q34: [m] | R34: [m] | S34: [m²] | T34: [m] | U34: [m]
B55: Total | I55: =SUM(I35:I54) -> 0 | N55: =SUM(N35:N54) -> 0 | R55: =SUM(R35:R54) -> 0
B58: Ambiente | E58: Emassamento | I58: Lixamento | M58: Selamento | Q58: Pintura Acrílica | U58: Pintura Esmalte
E59: h | F59: Per | G59: A [m²] | I59: h | J59: Per | K59: A [m²] | M59: h | N59: Per | O59: A [m²] | Q59: A [m²] | U59: A [m²]
E60: [m] | F60: [m] | G60: Parede | H60: Teto | I60: [m] | J60: [m] | K60: Parede | L60: Teto | M60: [m] | N60: [m] | O60: Parede | P60: Teto | Q60: Parede | R60: Teto | S60: Piso | T60: Pilar | U60: Portas | V60: Janelas | W60: Grades
B81: Total | I81: =SUM(I61:I80) -> 0 | N81: =SUM(N61:N80) -> 0 | Q81: =SUM(Q61:Q80) -> 0 | R81: =SUM(R61:R80) -> 0 | S81: =SUM(S61:S80) -> 0 | T81: =SUM(T61:T80) -> 0 | U81: =SUM(U61:U80) -> 0 | V81: =SUM(V61:V80) -> 0 | W81: =SUM(W61:W80) -> 0
E84: Portas e Alçapões | K84: Janelas e Visores | Q84: Telas | U84: Vidros | Y84: Venezianas Industriais | AD84: Protetores de Canto | AG84: Protetores de Parede | AJ84: Grades
B85: Ambiente | E85: P/A | F85: Qtd | G85: L | H85: h | I85: e | J85: A | K85: J/V | L85: Qtd | M85: L | N85: h | O85: e | P85: A | Q85: L | R85: h | S85: Qtd | T85: A [m2] | U85: L | V85: h | W85: Qtd | X85: A [m2] | Y85: Peça | Z85: L | AA85: h | AB85: Qtd | AC85: A [m2] | AD85: L | AE85: e | AF85: C | AG85: L | AH85: e | AI85: C | AJ85: Tipo | AK85: A | AL85: Malha | AM85: e | AN85: Afastamento [cm]
G86: [cm] | H86: [cm] | I86: [cm] | J86: [m2] | M86: [cm] | N86: [cm] | O86: [cm] | P86: [m2] | Q86: [cm] | R86: [cm] | U86: [cm] | V86: [cm] | Z86: [cm] | AA86: [cm] | AD86: [cm] | AE86: [mm] | AF86: [m] | AG86: [cm] | AH86: [mm] | AI86: [m] | AK86: [m2] | AL86: [cm] | AM86: [mm] | AN86: Janela | AO86: Alvenaria
B107: Total | I107: =SUM(I87:I106) -> 0 | N107: =SUM(N87:N106) -> 0 | T107: =SUM(T87:T106) -> 0 | X107: =SUM(X87:X106) -> 0 | AC107: =SUM(AC87:AC106) -> 0
E110: Acessórios | K110: Barras de Apoio | O110: Corrimãos e Guarda-Corpos
B111: Ambiente | E111: Bacias Sanitárias | F111: Mictórios | G111: Lavatórios | H111: Cubas | I111: Tanques | J111: Torneiras | K111: Qtd | L111: C | M111: ø | N111: h Piso | O111: Qtd | P111: C | Q111: ø | R111: h Piso
L112: [m] | M112: [mm] | N112: [m] | P112: [m] | Q112: [mm] | R112: [m]
B133: Total | I133: =SUM(I113:I132) -> 0 | N133: =SUM(N113:N132) -> 0
E136: Bancadas e Pias | P136: Divisórias | X136: Boxes
B137: Ambiente | E137: Dimensões | G137: Tampo | J137: Frontão | M137: Saia | P137: Tipo | Q137: Qtd | R137: Peça | U137: Portas | X137: Tipo | Y137: Qtd | Z137: Peça
E138: A | F138: h | G138: L | H138: C | I138: e | J138: L | K138: C | L138: e | M138: L | N138: C | O138: e | R138: C | S138: h | T138: A | U138: L | V138: h | W138: A | Z138: L | AA138: C | AB138: e | AC138: Sobreposição | AD138: A
E139: [m²] | F139: [m] | G139: [m] | H139: [m] | I139: [m] | J139: [m] | K139: [m] | L139: [m] | M139: [m] | N139: [m] | O139: [m] | R139: [m] | S139: [m] | T139: [m²] | U139: [m] | V139: [m] | W139: [m²] | Z139: [cm] | AA139: [cm] | AB139: [mm] | AC139: [cm] | AD139: [m²]
B160: Total | I160: =SUM(I140:I159) -> 0 | N160: =SUM(N140:N159) -> 0 | T160: =SUM(T140:T159) -> 0 | W160: =SUM(W140:W159) -> 0 | AD160: =SUM(AD140:AD159) -> 0
E163: Mobiliário
B164: Ambiente | E164: Tipo | F164: Dimensões [m] | I164: A
F165: h | G165: L | H165: C | I165: [m²]
B186: Total | I186: =SUM(I166:I185) -> 0

Sheet Inst Hidráulicas
B1: ='Levantamento Campo'!B1 -> Prj Estande de Tiro (50 m) – 5º BIL (Amv)

Sheet Inst Elétricas
B1: ='Levantamento Campo'!B1 -> Prj Estande de Tiro (50 m) – 5º BIL (Amv)
B3: CIRCUITOS AÉREOS
F4: Cabeamentos | N4: Postes | P4: Cruzetas | R4: Suportes | T4: Isoladores
B5: Local | E5: Circuito | F5: Qtd Cabos | G5: C [m] / A [mm²] | N5: ø | O5: C | P5: L | Q5: C | R5: L | S5: C | T5: ø | U5: C
G6: 1.5 | H6: 2.5 | I6: 4 | J6: 10 | K6: 16 | L6: 25 | M6: 100 | N6: [m] | O6: [m] | P6: [m] | Q6: [m] | R6: [m] | S6: [m] | T6: [m] | U6: [m]
B24: Total | G24: =SUM(G7:G23) -> 0 | H24: =SUM(H7:H23) -> 0 | I24: =SUM(I7:I23) -> 0 | J24: =SUM(J7:J23) -> 0 | K24: =SUM(K7:K23) -> 0 | L24: =SUM(L7:L23) -> 0 | M24: =SUM(M7:M23) -> 0 | O24: =SUM(O7:O23) -> 0 | Q24: =SUM(Q7:Q23) -> 0 | S24: =SUM(S7:S23) -> 0 | U24: =SUM(U7:U23) -> 0
B27: CIRCUITOS SUBTERRÂNEOS
N28: Eletroduto
F29: Cabeamento | N29: Metálico | P29: Corrugado | R29: PVC Liso
B30: Local | E30: Circuito | F30: Qtd Cabos | G30: C [m] / A [mm²] | N30: DN | O30: C | P30: DN | Q30: C | R30: DN | S30: C
G31: 1.5 | H31: 2.5 | I31: 4 | J31: 10 | K31: 16 | L31: 25 | M31: 100 | N31: [mm] | O31: [m] | P31: [mm] | Q31: [m] | R31: [mm] | S31: [m]
B49: Total | G49: =SUM(G32:G48) -> 0 | H49: =SUM(H32:H48) -> 0 | I49: =SUM(I32:I48) -> 0 | J49: =SUM(J32:J48) -> 0 | K49: =SUM(K32:K48) -> 0 | L49: =SUM(L32:L48) -> 0 | M49: =SUM(M32:M48) -> 0 | O49: =SUM(O32:O48) -> 0 | Q49: =SUM(Q32:Q48) -> 0 | S49: =SUM(S32:S48) -> 0
B52: CIRCUITOS INTERNOS
F54: Quadros de Energia | K54: Cabeamentos | P54: Dutos | AL54: Aterramento
B55: Local | E55: Circuito | F55: Tipo | G55: Qtd Disjuntores | K55: A [mm²] | P55: Eletrocalha | U55: Eletroduto | AL55: Haste | AO55: Caixa Inspeção
K56: 1.5 | L56: 2.5 | M56: 4 | N56: 10 | O56: 16 | P56: L | Q56: h | R56: C | S56: Septo Elétrica | T56: Septo Lógica | U56: DN | V56: C | W56: Conduletes | AF56: Tomadas | AH56: Interruptores | AJ56: Luminárias | AL56: DN | AM56: C | AN56: Qtd | AO56: Qtd | AP56: DN | AQ56: h
K57: C [m] | L57: C [m] | M57: C [m] | N57: C [m] | O57: C [m] | P57: [cm] | Q57: [cm] | R57: [m] | S57: [cm] | T57: [cm] | U57: [mm] | V57: [m] | W57: B | X57: C | Y57: E | Z57: LL | AA57: LR | AB57: LB | AC57: TB | AD57: T | AE57: X | AF57: Tipo | AG57: Qtd | AH57: Tipo | AI57: Qtd | AJ57: Tipo | AK57: Qtd | AL57: [pol] | AM57: [m] | AP57: [pol] | AQ57: [mm]
B75: Total | H75: =SUM(H58:H74) -> 0 | I75: =SUM(I58:I74) -> 0 | J75: =SUM(J58:J74) -> 0 | K75: =SUM(K58:K74) -> 0 | L75: =SUM(L58:L74) -> 0 | M75: =SUM(M58:M74) -> 0 | N75: =SUM(N58:N74) -> 0 | O75: =SUM(O58:O74) -> 0 | R75: =SUM(R58:R74) -> 0 | V75: =SUM(V58:V74) -> 0 | W75: =SUM(W58:W74) -> 0 | X75: =SUM(X58:X74) -> 0 | Y75: =SUM(Y58:Y74) -> 0 | Z75: =SUM(Z58:Z74) -> 0 | AA75: =SUM(AA58:AA74) -> 0 | AB75: =SUM(AB58:AB74) -> 0 | AC75: =SUM(AC58:AC74) -> 0 | ... AE75: =SUM(AE58:AE74) -> 0 | AG75: =SUM(AG58:AG74) -> 0 | AI75: =SUM(AI58:AI74) -> 0 | AK75: =SUM(AK58:AK74) -> 0 | AM75: =SUM(AM58:AM74) -> 0 | AN75: =SUM(AN58:AN74) -> 0 | AO75: =SUM(AO58:AO74) -> 0

Sheet Inst de Telefonia e Rede
B1: ='Levantamento Campo'!B1 -> Prj Estande de Tiro (50 m) – 5º BIL (Amv)
F4: Quadros de Rede | H4: Cabeamentos | M4: Dutos | AE4: Aterramento
E5: Circuito | F5: Tipo | G5: Qtd | H5: Rede | I5: Patch Cord | J5: Câmera | K5: TV | L5: Telefonia | M5: Eletrocalha | P5: Septo | R5: Eletroduto | AE5: Haste | AH5: Caixa Inspeção
B6: Local | M6: L | N6: h | O6: C | P6: Elétrica | Q6: Lógica | R6: DN | S6: C | T6: Conduletes | AC6: Tomadas | AE6: DN | AF6: C | AG6: Qtd | AH6: Qtd | AI6: DN | AJ6: h
H7: C [m] | I7: C [m] | J7: C [m] | K7: C [m] | L7: C [m] | M7: [cm] | N7: [cm] | O7: [m] | P7: [cm] | Q7: [cm] | R7: [mm] | S7: [m] | T7: B | U7: C | V7: E | W7: LL | X7: LR | Y7: LB | Z7: TB | AA7: T | AB7: X | AC7: RJ 45 | AD7: Keystone | AE7: [pol] | AF7: [m] | AI7: [pol] | AJ7: [mm]
B25: Total | H25: =SUM(H8:H24) -> 0 | I25: =SUM(I8:I24) -> 0 | J25: =SUM(J8:J24) -> 0 | K25: =SUM(K8:K24) -> 0 | L25: =SUM(L8:L24) -> 0 | O25: =SUM(O8:O24) -> 0 | S25: =SUM(S8:S24) -> 0 | T25: =SUM(T8:T24) -> 0 | U25: =SUM(U8:U24) -> 0 | V25: =SUM(V8:V24) -> 0 | W25: =SUM(W8:W24) -> 0 | X25: =SUM(X8:X24) -> 0 | Y25: =SUM(Y8:Y24) -> 0 | Z25: =SUM(Z8:Z24) -> 0 | ... AB25: =SUM(AB8:AB24) -> 0 | AD25: =SUM(AD8:AD24) -> 0 | AF25: =SUM(AF8:AF24) -> 0 | AG25: =SUM(AG8:AG24) -> 0 | AH25: =SUM(AH8:AH24) -> 0

Sheet Inst Mecânicas
B1: ='Levantamento Campo'!B1 -> Prj Estande de Tiro (50 m) – 5º BIL (Amv)
E4: Ar Condicionado | K4: Ventilador | M4: Exaustor
E5: Qtd | F5: Pot | G5: Mat Complementar | K5: Qtd | L5: Tipo | M5: Qtd | N5: Tipo
G6: Dutos | I6: Cabo Elétrico | J6: Gás Refrig
B7: Ambiente | G7: Refrig | H7: Dreno
F8: [BTU] | G8: [m] | H8: [m] | I8: [KgF] | J8: [m]
B28: Total | E28: =SUM(E9:E27) -> 0 | G28: =SUM(G9:G27) -> 0 | H28: =SUM(H9:H27) -> 0 | I28: =SUM(I9:I27) -> 0 | J28: =SUM(J9:J27) -> 0 | K28: =SUM(K9:K27) -> 0 | M28: =SUM(M9:M27) -> 0

Sheet Inst Pressurizadas
B1: ='Levantamento Campo'!B1 -> Prj Estande de Tiro (50 m) – 5º BIL (Amv)
B4: Circuito | E4: Gás Pressurizado | U4: Conexões
E5: Dutos | H5: Reguladores | M5: Válvulas | P5: Registros | S5: Reservatórios | U5: Tipo | V5: Joelhos | X5: Curva | Y5: Luvas | AA5: Tês | AC5: Junções
E6: DN | F6: h | G6: C | H6: DN | I6: Qtd | J6: Tipo | K6: Redução Pressão | M6: DN | N6: Qtd | O6: Tipo | P6: DN | Q6: Qtd | R6: Tipo | S6: Qtd | T6: Tipo | V6: 90° | W6: 45° | X6: 90° | Y6: Simples | Z6: Redução | AA6: Simples | AB6: Redução | AC6: 45° | AD6: Redução
E7: [mm] | F7: [cm] | G7: [m] | H7: [mm] | K7: de | L7: para | M7: [mm] | P7: [mm] | U7: DN
B17: Total | G17: =SUM(G8:G16) -> 0 | I17: =SUM(I8:I16) -> 0 | N17: =SUM(N8:N16) -> 0 | Q17: =SUM(Q8:Q16) -> 0 | S17: =SUM(S8:S16) -> 0 | V17: =SUM(V7:V16) -> 0 | W17: =SUM(W7:W16) -> 0 | X17: =SUM(X7:X16) -> 0 | Y17: =SUM(Y7:Y16) -> 0 | Z17: =SUM(Z7:Z16) -> 0 | AA17: =SUM(AA7:AA16) -> 0 | AB17: =SUM(AB7:AB16) -> 0 | AC17: =SUM(AC7:AC16) -> 0 | AD17: =SUM(AD7:AD16) -> 0

Sheet Inst de Segurança
B1: ='Levantamento Campo'!B1 -> Prj Estande de Tiro (50 m) – 5º BIL (Amv)
E4: Terminais | I4: Captação | N4: Equalização | P4: Aterramento
E5: Qtd | F5: Dimensões | I5: Barra | J5: Cordoalha | K5: Duto | L5: Terminal Compressão | M5: Fixação | N5: Cordoalha | O5: Grampo | P5: Haste | S5: Caixa Inspeção
B6: Ambiente | F6: L | G6: e | H6: C | P6: DN | Q6: C | R6: Qtd | S6: Qtd | T6: DN | U6: h
F7: [pol] | G7: [pol] | H7: [mm] | I7: [m] | J7: [m] | K7: [m] | P7: [pol] | Q7: [m] | T7: [pol] | U7: [mm]
B17: Total | E17: =SUM(E8:E16) -> 0 | I17: =SUM(I8:I16) -> 0 | J17: =SUM(J8:J16) -> 0 | K17: =SUM(K8:K16) -> 0 | L17: =SUM(L8:L16) -> 0 | M17: =SUM(M8:M16) -> 0 | N17: =SUM(N8:N16) -> 0 | O17: =SUM(O8:O16) -> 0 | Q17: =SUM(Q8:Q16) -> 0 | R17: =SUM(R8:R16) -> 0 | S17: =SUM(S8:S16) -> 0
J20: Hidrantes | X20: Conexões
E21: Extintores Portáteis | J21: Qtd | K21: Dimensões | N21: Visor | Q21: Duto de Contra Incêndio | T21: Registro | V21: Válvula | X21: Tipo | Y21: Joelhos | AA21: Curva | AB21: Luvas | AD21: Tês | AF21: Junções
B22: Ambiente | E22: Local | F22: Tipo | G22: Peso | H22: Cpcd Extint Mín | I22: Qtd | K22: L | L22: Prof | M22: h | N22: L | O22: e | P22: C | Q22: DN | R22: h | S22: C | T22: DN | U22: Qtd | V22: DN | W22: Qtd | Y22: 90° | Z22: 45° | AA22: 90° | AB22: Simples | AC22: Redução | AD22: Simples | AE22: Redução | AF22: 45° | AG22: Redução
G23: [KgF] | K23: [cm] | L23: [cm] | M23: [cm] | N23: [cm] | O23: [mm] | P23: [cm] | Q23: [pol] | R23: [cm] | S23: [m] | T23: [pol] | V23: [pol] | X23: DN
S33: =SUM(S24:S32) -> 0
S34: =SUM(S25:S33) -> 0
S35: =SUM(S26:S34) -> 0
S36: =SUM(S27:S35) -> 0
S37: =SUM(S28:S36) -> 0
S38: =SUM(S29:S37) -> 0
S39: =SUM(S30:S38) -> 0
S40: =SUM(S31:S39) -> 0
S41: =SUM(S32:S40) -> 0
S42: =SUM(S33:S41) -> 0
B43: Total | I43: =SUM(I24:I42) -> 0 | J43: =SUM(J34:J42) -> 0 | S43: =SUM(S34:S42) -> 0 | U43: =SUM(U34:U42) -> 0 | W43: =SUM(W34:W42) -> 0 | Y43: =SUM(Y33:Y42) -> 0 | Z43: =SUM(Z33:Z42) -> 0 | AA43: =SUM(AA33:AA42) -> 0 | AB43: =SUM(AB33:AB42) -> 0 | AC43: =SUM(AC33:AC42) -> 0 | AD43: =SUM(AD33:AD42) -> 0 | AE43: =SUM(AE33:AE42) -> 0 | AF43: =SUM(AF33:AF42) -> 0 | AG43: =SUM(AG33:AG42) -> 0

Sheet Comunicações Ambientais
B1: ='Levantamento Campo'!B1 -> Prj Estande de Tiro (50 m) – 5º BIL (Amv)
E4: Plaquetas | N4: Sinalização de Via
B5: Ambiente | E5: Local | F5: Saída | G5: Extintor | H5: Quadro Força | I5: Hidrante | J5: Alarme | K5: Proibido Fumar | L5: Perigo Inflamável | M5: Risco Explosão | N5: Contra Mão | O5: Curva Direita | P5: Curva Esquerda | Q5: 40 Km/h | R5: Pare
B27: Total | F27: =SUM(F7:F26) -> 0 | G27: =SUM(G7:G26) -> 0 | H27: =SUM(H7:H26) -> 0 | I27: =SUM(I7:I26) -> 0 | J27: =SUM(J7:J26) -> 0 | K27: =SUM(K7:K26) -> 0 | L27: =SUM(L7:L26) -> 0 | M27: =SUM(M7:M26) -> 0 | ... T27: =SUM(T7:T26) -> 0

Sheet Paisagismos
B1: ='Levantamento Campo'!B1 -> Prj Estande de Tiro (50 m) – 5º BIL (Amv)
B5: Ambiente | C5: Local

Sheet Entrega da Obra
B1: ='Levantamento Campo'!B1 -> Prj Estande de Tiro (50 m) – 5º BIL (Amv)
